Workbook

Sheet DailyVariables
A1: Date | B1: VIX | C1: VIX3M | D1: VIX/VIX3M | E1: MOVE | F1: DXY | G1: HY_OAS | H1: NFCI | I1: Intermediary_Cap_Ratio | J1: Intermediary_Cap_Z | K1: DGS2 | L1: DGS10 | M1: 2s10s | N1: DFII10 | O1: T10YIE | P1: ACM_TP_10Y | Q1: SPX | R1: NDX | S1: SPY | T1: QQQ | U1: EWJ | V1: EWY | W1: NVDA | X1: TSLA | Y1: TSM | Z1: AAPL | AA1: GOOGL | AB1: AMZN | AC1: META | AD1: INTC | AE1: MU | AF1: PYPL | AG1: PLTR | AH1: WDC | AI1: ResidMom_NVDA | AJ1: ResidMom_TSLA | AK1: ResidMom_TSM | AL1: ResidMom_AAPL | AM1: ResidMom_GOOGL | AN1: ResidMom_AMZN | AO1: ResidMom_META | AP1: ResidMom_INTC | AQ1: ResidMom_MU | AR1: ResidMom_PYPL | AS1: ResidMom_PLTR | AT1: ResidMom_WDC | AU1: Brent | AV1: WTI | AW1: Gold | AX1: Silver | AY1: Copper | AZ1: Platinum | BA1: Palladium | BB1: BasisMom_Brent_4w | BC1: BasisMom_Brent_12w | BD1: BasisMom_WTI_4w | BE1: BasisMom_WTI_12w | BF1: BasisMom_Gold_4w | BG1: BasisMom_Gold_12w | BH1: BasisMom_Silver_4w | BI1: BasisMom_Silver_12w | BJ1: BasisMom_Copper_4w | BK1: BasisMom_Copper_12w | BL1: EURUSD | BM1: USDJPY | BN1: BTC | BO1: ETH | BP1: BTC_HashRate | BQ1: BTC_ActiveAddr | BR1: BTC_ExchNetflow | BS1: BTC_ETF_Flow | BT1: BTC_PerpFunding | BU1: BTC_3mBasis | BV1: ETH_ETF_Flow | BW1: ETH_DailyTxns | BX1: GradeA_Missing_Count | BY1: Source_Brief
A2: 46126 | B2: 29 | F2: 98.13 | K2: 3.77 | L2: 4.359 | N2: 1.9 | O2: 2.36 | R2: 6886 | V2: 141.23 | Y2: 370.6 | AB2: 238.38 | AC2: 634.53 | AU2: 94.79 | AV2: 91.28 | AW2: 4761.42 | AX2: 75.6 | AY2: 6.01 | BD2: 1.1769 | BF2: 75900 | BG2: 2329 | BL2: 1.1769 | BM2: 159.28 | BN2: 75900 | BQ2: 364000 | BR2: -7900 | BV2: 4 | BX2: 4 | BY2: market-brief-2026-04-14.md
A3: 46127 | B3: 18.36 | C3: 21.86 | E3: 74.35 | F3: 98.09 | G3: 2.94 | H3: -0.43 | I3: 0.14 | J3: 1.86 | K3: 3.77 | L3: 4.29 | M3: 0.52 | N3: 1.9 | O3: 2.36 | Q3: 6967.38 | S3: 694.46 | T3: 628.6 | V3: 146.68 | W3: 195.88 | X3: 364 | Y3: 379.89 | Z3: 259 | AA3: 318 | AB3: 248 | AC3: 662 | AD3: 63 | AE3: 465.66 | AF3: 48 | AG3: 136 | AH3: 366 | AI3: -30.67 | AJ3: -44.21 | AK3: -19.78 | AL3: -3.89 | AM3: -0.2 | AN3: -7.2 | AO3: -25.25 | AP3: 42.33 | AQ3: 1.44 | AR3: -47.46 | AS3: -100.26 | AT3: 20.62 | AU3: 95.72 | AV3: 91.5 | AW3: 4830 | AX3: 79.67 | AY3: 6.01 | AZ3: 2108 | BB3: 3.95 | BC3: 4.05 | BD3: 6.6 | BE3: 6.7 | BF3: -19 | BG3: -20 | BH3: -0.28 | BI3: -0.3 | BJ3: 0.08 | BK3: 0.09 | BL3: 1.1769 | BM3: 159.28 | BN3: 74294 | BO3: 2329 | BP3: 1033 | BQ3: 364000 | BR3: -7900 | BS3: 411.5 | BV3: 187 | BW3: 3600000 | BX3: 4 | BY3: market-brief-2026-04-15.md v1 + trade-rec v3
A4: 46128 | B4: 18.19 | C4: 20.78 | E4: 67.94 | F4: 98.17 | G4: 2.95 | H4: -0.47 | K4: 3.77 | L4: 4.276 | M4: 0.506 | N4: 1.89 | O4: 2.36 | Q4: 7000 | S4: 699.94 | T4: 637.4 | U4: 89.07 | V4: 144.92 | W4: 198.87 | X4: 391.95 | Y4: 375.1 | Z4: 266.43 | AA4: 337.12 | AB4: 248.5 | AC4: 671.58 | AD4: 64.94 | AE4: 456.23 | AF4: 49.57 | AG4: 142.15 | AH4: 365 | AU4: 96.51 | AV4: 89.21 | AW4: 4840.2 | AX4: 79.59 | AY4: 6.096 | AZ4: 2144.6 | BA4: 1587.5 | BL4: 1.1786 | BM4: 159.02 | BN4: 74914 | BO4: 2347 | BP4: 863.5 | BQ4: 470280 | BS4: 411.5 | BV4: 9.44 | BX4: 4 | BY4: market-brief-2026-04-16.md v1
A5: 46129 | B5: 17.92 | C5: 20.59 | D5: 0.87 | E5: 65.89 | F5: 97.8 | G5: 295 | H5: -0.47 | I5: 0.1261 | J5: 0.18 | K5: 3.78 | L5: 4.228 | M5: 0.448 | N5: 1.89 | O5: 2.34 | P5: 0.59 | S5: 710.82 | T5: 649.13 | U5: 90.63 | V5: 153.72 | W5: 200.83 | X5: 404.37 | Y5: 368.92 | Z5: 271.52 | AA5: 336.9 | AB5: 254.41 | AC5: 685.17 | AD5: 69.92 | AE5: 460 | AF5: 50.96 | AG5: 148.13 | AH5: 371 | AI5: -1 | AJ5: -9.12 | AK5: 1 | AL5: 4.68 | AM5: -0.8 | AN5: 1.39 | AO5: 0.75 | AP5: 13.89 | AQ5: 15.63 | AR5: -5.25 | AS5: -35.62 | AT5: 2.38 | AU5: 86.65 | AV5: 79.46 | AW5: 4897.9 | AX5: 82.995 | AY5: 6.1135 | AZ5: 2145.2 | BA5: 1606.5 | BB5: 3.5 | BC5: 3.5 | BD5: 6.98 | BE5: 6.98 | BF5: -20 | BG5: -20 | BH5: -0.29 | BI5: -0.29 | BJ5: 0.09 | BK5: 0.09 | BL5: 1.1818 | BM5: 157.92 | BN5: 77775 | BO5: 2443 | BP5: 1050 | BQ5: 470280 | BS5: 186 | BT5: negative 46+ days | BX5: 0 | BY5: market-brief-2026-04-17 v3

Sheet SignalLedger
A1: ID | B1: Type | C1: Date | D1: Asset | E1: AssetClass | F1: Direction | G1: S | H1: T | I1: C | J1: R | K1: Sum | L1: Entry_Price | M1: ATR_Stop | N1: Target_TP1 | O1: Target_TP2 | P1: Invalidation | Q1: Inv_Date | R1: VIX_at_Entry | S1: Regime_Label | T1: Blocking_Leg | U1: Block_Reason | V1: Taken | W1: Status | X1: Exit_Price | Y1: Exit_Date | Z1: Days_to_Exit | AA1: MAE_Pct | AB1: MFE_Pct | AC1: Catalyst_Outcome | AD1: Hypo_PnL_Pct | AE1: Source_File | AF1: Notes
A2: P001 | B2: Promoted | C2: 46127 | D2: EWY | E2: ETFs/Indices | F2: Long | G2: 1 | H2: 1 | I2: 1 | J2: 0 | K2: 3 | L2: 144.1 | M2: 133 | N2: 156 | O2: 166 | P2: TSM miss / KOSPI <5800 / DXY >100 | Q2: 46155 | R2: 18.36 | S2: Post-shock cautious risk-on | V2: YES | W2: HIT_STOP | X2: 145.39 | Y2: 46128 | Z2: 1 | AD2: 0.9 | AE2: trade-rec-2026-04-15.md v1 | AF2: First promoted signal. Checklist 6/6 PASS. TAKEN 2026-04-15 22:36 UTC+8. Limit buy filled at $144.10 ($299.73 USDT). Within entry zone $143-$148. | EXIT 2026-04-16 21:55 UTC+8 stop-market @ $145.39. Held ~23h. Protective stop was tightened to ~0.9% above entry (well inside methodology ATR stop of $133); tripped on post-TSM chop before thesis played out. Reconciled 2026-04-17.
A3: P002 | B3: Promoted | C3: 46127 | D3: TSM | E3: Equities | F3: Long | G3: 1 | H3: 1 | I3: 1 | J3: 0 | K3: 3 | L3: 370.6 | M3: 334 | N3: 397 | O3: 424 | P3: Q1 miss / KOSPI <5800 / DXY >100 | Q3: 46155 | R3: 18.36 | S3: Post-shock cautious risk-on | V3: CONDITIONAL | W3: DE-PROMOTED | AE3: trade-rec-2026-04-15.md v2 | AF3: v3 DE-PROMOTION: residual flipped to -19.78% (T=-1). Sum +3→+1.
A4: P003 | B4: Promoted | C4: 46127 | D4: INTC | E4: Equities | F4: Long | G4: 1 | H4: 1 | I4: 1 | J4: 0 | K4: 3 | L4: 64.68 | M4: 56 | N4: 70 | O4: 77 | P4: Earnings miss / Terafab delay / trend break <$55 | Q4: 46155 | R4: 18.36 | S4: Post-shock cautious risk-on | V4: YES | W4: OPEN | AE4: trade-rec-2026-04-15.md v3 | AF4: Residual +42.33% T=+1. Semi-correlated with EWY. TAKEN 2026-04-16 09:29 UTC+8. Market buy filled at $64.68 ($49.81 USDT). Above rec entry zone $60-$64; size reduced accordingly.
A5: N001 | B5: Near-Miss | C5: 46126 | D5: EWY | E5: ETFs/Indices | F5: Long | G5: 1 | H5: 1 | I5: 1 | J5: 0 | K5: 3 | S5: Energy-led reflation shock | T5: fail-loud | U5: Intermediary capital MISSING | W5: STILL_OPEN | AE5: trade-rec-2026-04-14.md | AF5: Sum=+3 on paper but checklist cannot pass.
A6: N002 | B6: Near-Miss | C6: 46126 | D6: Copper | E6: Commodities | F6: Long | G6: 1 | H6: 1 | I6: 0 | J6: 0 | K6: 2 | S6: Energy-led reflation shock | T6: C | U6: No imminent catalyst | W6: STILL_OPEN | AE6: trade-rec-2026-04-14.md | AF6: Cleanest S+T in metals; awaiting China data
A7: N003 | B7: Near-Miss | C7: 46126 | D7: Gold | E7: Commodities | F7: Long | G7: 1 | H7: 1 | I7: 1 | J7: -1 | K7: 2 | S7: Energy-led reflation shock | T7: R | U7: Crowded positioning | W7: STILL_OPEN | AE7: trade-rec-2026-04-14.md | AF7: Correlation-gated with Silver/Copper
A8: N004 | B8: Near-Miss | C8: 46126 | D8: Silver | E8: Commodities | F8: Long | G8: 1 | H8: 1 | I8: 1 | J8: -1 | K8: 2 | S8: Energy-led reflation shock | T8: R | U8: Crowded alongside gold | W8: STILL_OPEN | AE8: trade-rec-2026-04-14.md | AF8: Silver squeeze industrial demand breakout
A9: N005 | B9: Near-Miss | C9: 46126 | D9: Brent | E9: Commodities | F9: Long | G9: 1 | H9: 1 | I9: 1 | J9: -1 | K9: 2 | S9: Energy-led reflation shock | T9: R | U9: Positioning crowded long on geopolitical premium | W9: STILL_OPEN | AE9: trade-rec-2026-04-14.md | AF9: Deep backwardation; basis-momentum MISSING
A10: N006 | B10: Near-Miss | C10: 46126 | D10: WTI | E10: Commodities | F10: Long | G10: 1 | H10: 1 | I10: 1 | J10: -1 | K10: 2 | S10: Energy-led reflation shock | T10: R | U10: Positioning crowded long on geopolitical premium | W10: STILL_OPEN | AE10: trade-rec-2026-04-14.md | AF10: Basis-momentum divergence cap fired Apr-15
A11: N007 | B11: Near-Miss | C11: 46126 | D11: TSM | E11: Equities | F11: Long | G11: 1 | H11: 1 | I11: 1 | J11: 0 | K11: 3 | S11: Energy-led reflation shock | T11: fail-loud | U11: Residual momentum MISSING → PROMOTED to P002 | W11: PROMOTED | AE11: trade-rec-2026-04-14.md | AF11: Graduated to P002 v2
A12: N008 | B12: Near-Miss | C12: 46126 | D12: AMZN | E12: Equities | F12: Long | G12: 1 | H12: -1 | I12: 1 | J12: 0 | K12: 1 | S12: Energy-led reflation shock | T12: T | U12: Residual -9.3% (T=-1) | W12: STILL_OPEN | AE12: trade-rec-2026-04-14.md | AF12: v2 DEMOTED from +2
A13: N009 | B13: Near-Miss | C13: 46126 | D13: META | E13: Equities | F13: Long | G13: 1 | H13: -1 | I13: 1 | J13: 0 | K13: 1 | S13: Energy-led reflation shock | T13: T | U13: Residual -12.1% (T=-1) | W13: STILL_OPEN | AE13: trade-rec-2026-04-14.md | AF13: v2 DEMOTED from +2
A14: N010 | B14: Near-Miss | C14: 46127 | D14: Gold | E14: Commodities | F14: Long | G14: 1 | H14: 1 | I14: 0 | J14: 0 | K14: 2 | R14: 18.36 | S14: Post-shock cautious risk-on | T14: C | U14: No near-term surprise catalyst | W14: OPEN | AE14: trade-rec-2026-04-15.md v3 | AF14: Trigger: DXY <97.5 or VIX spike
A15: N011 | B15: Near-Miss | C15: 46127 | D15: Silver | E15: Commodities | F15: Long | G15: 1 | H15: 1 | I15: 0 | J15: 0 | K15: 2 | R15: 18.36 | S15: Post-shock cautious risk-on | T15: C | U15: No catalyst beyond gold sympathy | W15: OPEN | AE15: trade-rec-2026-04-15.md v3 | AF15: Breakout holding $79.67
A16: N012 | B16: Near-Miss | C16: 46127 | D16: Brent | E16: Commodities | F16: Long | G16: 1 | H16: 1 | I16: -1 | J16: 0 | K16: 1 | R16: 18.36 | S16: Post-shock cautious risk-on | T16: C | U16: Iran ceasefire Apr-21 hostile catalyst | W16: OPEN | AE16: trade-rec-2026-04-15.md v3 | AF16: Binary on Iran talks collapse
A17: N013 | B17: Near-Miss | C17: 46127 | D17: WDC | E17: Equities | F17: Long | G17: 1 | H17: 1 | I17: 0 | J17: 0 | K17: 2 | R17: 18.36 | S17: Post-shock cautious risk-on | T17: C | U17: No fresh catalyst | W17: OPEN | AE17: trade-rec-2026-04-15.md v3 | AF17: Residual +20.62% T=+1
A18: N014 | B18: Near-Miss | C18: 46127 | D18: TSM | E18: Equities | F18: Long | G18: 1 | H18: -1 | I18: 1 | J18: 0 | K18: 1 | R18: 18.36 | S18: Post-shock cautious risk-on | T18: T | U18: Residual -19.78% (T=-1) | W18: OPEN | AE18: trade-rec-2026-04-15.md v3 | AF18: v3 de-promotion from P002
A19: N015 | B19: Near-Miss | C19: 46128 | D19: Copper | E19: Commodities | F19: Long | G19: 1 | H19: 1 | I19: 0 | J19: 0 | K19: 2 | R19: 18.17 | S19: Post-shock cautious risk-on, accelerating but narrowing | T19: C | U19: No catalyst (need China PMI >50.5) | W19: OPEN | AE19: trade-rec-2026-04-16.md v2 | AF19: Unchanged from prior
A20: N016 | B20: Near-Miss | C20: 46128 | D20: Brent | E20: Commodities | F20: Long | G20: 1 | H20: 1 | I20: -1 | J20: 1 | K20: 2 | R20: 18.17 | S20: Post-shock cautious risk-on, accelerating but narrowing | T20: C | U20: Iran ceasefire hostile catalyst; extension in principle | W20: OPEN | AE20: trade-rec-2026-04-16.md v2 | AF20: Binary on Apr-21; failed to rally on bullish EIA
A21: N017 | B21: Near-Miss | C21: 46128 | D21: TSM | E21: Equities | F21: Long | G21: 1 | H21: -1 | I21: 0 | J21: 0 | K21: 0 | R21: 18.17 | S21: Post-shock cautious risk-on, accelerating but narrowing | T21: T | U21: Residual -19.78% (T=-1); post-catalyst C=0 | W21: OPEN | AE21: trade-rec-2026-04-16.md v2 | AF21: Q1 beat but T-block persists
A22: P004 | B22: Promoted | C22: 46128 | D22: Gold | E22: Commodities | F22: Long | G22: 1 | H22: 1 | I22: 1 | J22: 0 | K22: 3 | L22: 4840 | M22: 4640 | N22: 4990 | O22: 5140 | P22: DXY >100; DFII10 >2.2%; Gold <$4,640 | Q22: 46156 | R22: 18.19 | S22: Broad risk-on | V22: YES | W22: OPEN | AE22: trade-rec-2026-04-16.md v2 | AF22: Iran ceasefire Apr-21 = C+1. Basis-momentum MISSING but Gold S from DXY/real yields. Checklist 6/6 PASS. Reaffirmed v3: basis-momentum confirmed (contango, no divergence cap). | EXECUTED 2026-04-16 22:28 UTC+8 at actual fill $4,780.69 (trailing buy triggered ≤$4,798.34, 0.1% callback); size $396.80 USDT ~0.0830 oz. Fill BELOW stated entry zone $4,800–$4,860 — trailing stop caught the dip, favorable. Entry_Price kept as signal-time $4,840. Reconciled 2026-04-17.
A23: N018 | B23: Near-Miss | C23: 46128 | D23: SPY | E23: ETFs/Indices | F23: Long | G23: 1 | H23: 1 | I23: 0 | J23: 1 | K23: 3 | R23: 18.19 | S23: Broad risk-on | T23: Correlation | U23: Correlation gate with EWY/INTC; C=0 no catalyst; dominated by QQQ | W23: OPEN | AE23: trade-rec-2026-04-16.md v2 | AF23: Sum +3 but not promoted. FOMC Apr-28 risk.
A24: N019 | B24: Near-Miss | C24: 46128 | D24: QQQ | E24: ETFs/Indices | F24: Long | G24: 1 | H24: 1 | I24: 1 | J24: 1 | K24: 4 | R24: 18.19 | S24: Broad risk-on | T24: Correlation | U24: Correlation gate with EWY/INTC; FOMC Apr-28 risk; deferred to Gerald | W24: OPEN | AE24: trade-rec-2026-04-16.md v2 | AF24: Strongest signal (Sum +4). Flagged for Gerald evaluation. | Superseded by P005 promoted ad-hoc 2026-04-17 after overnight gap-test cleared. Status unchanged per protocol — signal-review still marks to market; cross-link prevents double-count.
A25: N020 | B25: Near-Miss | C25: 46128 | D25: GOOGL | E25: Equities | F25: Long | G25: 1 | H25: 1 | I25: 1 | J25: 0 | K25: 3 | P25: Earnings miss; trend break; DXY >100 | Q25: 46156 | R25: 18.19 | S25: Broad risk-on — equity records, vol compression, DXY sub-99. Iran binary Apr-21. | T25: Correlation | U25: Corr gate cautionary with EWY/INTC; deferred to Gerald; +6.01% rally raises bar | W25: OPEN | AE25: trade-rec-2026-04-16.md v3 | AF25: NEW v3 — T unblocked by residual +30.52% (audit staging). Sum +3. Flagged for Gerald. Earnings Apr-22.
A26: N021 | B26: Near-Miss | C26: 46128 | D26: TSM | E26: Equities | F26: Long | G26: 1 | H26: 1 | I26: 0 | J26: 0 | K26: 2 | P26: Earnings miss Q2; KOSPI <5800 | Q26: 46156 | R26: 18.19 | S26: Broad risk-on — equity records, vol compression, DXY sub-99. Iran binary Apr-21. | T26: C | U26: Post-catalyst C=0 (Q1 beat consumed). T flipped -1 to +1 (residual +21.59%) | W26: OPEN | AE26: trade-rec-2026-04-16.md v3 | AF26: Score change from N017. T upgraded -1→+1 via residual momentum (audit-addition). Sum 0→+2.
A27: N022 | B27: Near-Miss | C27: 46128 | D27: NVDA | E27: Equities | F27: Long | G27: 1 | H27: 1 | I27: 0 | J27: 0 | K27: 2 | P27: Trend break; no catalyst | Q27: 46156 | R27: 18.19 | S27: Broad risk-on — equity records, vol compression, DXY sub-99. Iran binary Apr-21. | T27: C | U27: No near-term catalyst. Residual +7.18% (weakest T=+1) | W27: OPEN | AE27: trade-rec-2026-04-16.md v3 | AF27: NEW v3 — T unblocked by residual +7.18%. Weak T=+1; could flip.
A28: N023 | B28: Near-Miss | C28: 46128 | D28: MU | E28: Equities | F28: Long | G28: 1 | H28: 1 | I28: 0 | J28: 0 | K28: 2 | P28: Trend break; earnings miss | Q28: 46156 | R28: 18.19 | S28: Broad risk-on — equity records, vol compression, DXY sub-99. Iran binary Apr-21. | T28: C | U28: No near-term catalyst. Residual +89.52% | W28: OPEN | AE28: trade-rec-2026-04-16.md v3 | AF28: NEW v3 — T unblocked by residual +89.52%. Strongest residual in universe.
A29: P005 | B29: Promoted | C29: 46129 | D29: QQQ | E29: ETFs/Indices | F29: Long | G29: 1 | H29: 1 | I29: 1 | J29: 1 | K29: 4 | L29: 640.09 | R29: 18.19 | S29: Broad risk-on | V29: YES | W29: OPEN | AE29: trade-rec-2026-04-16.md (promoted ad-hoc from N019) | AF29: Promoted ad-hoc from N019 (Sum=+4, flagged strongest signal). Two tranches: tranche 1 $198.10 @ $639.04 trailing buy fill 2026-04-17 00:02 UTC+8; tranche 2 $198.75 @ $641.14 limit fill 2026-04-17 00:13 UTC+8. Combined $396.85 USDT, avg entry $640.09. Reason for ad-hoc promotion: strongest NEW Sum+4 signal (TSM AI validation + NDX records + vol compression); blocking condition cleared overnight. Reconciled 2026-04-17.
A30: N024 | B30: Near-Miss | C30: 46129 | D30: GOOGL | E30: Equity-single | F30: Long | G30: 1 | H30: 0 | I30: 1 | J30: 0 | K30: 2 | L30: 336.9 | R30: 17.92 | S30: Broad risk-on — equity fresh highs, oil correction on Iran deal progress, vol compression deepening | T30: T | U30: Residual momentum -0.80% → T=0 (raw TSMOM +64.84% entirely factor-driven; trust residual per methodology). DOWNGRADED from +3 ref (Apr-16 N020) to +2 actual. | V30: No | W30: OPEN | AE30: trade-rec-2026-04-17.md v1 | AF30: Audit-addition (residual-mom) decision-moving BLOCK. Earnings Apr-22 critical binary; C+1 at ceiling without T.
A31: N025 | B31: Near-Miss | C31: 46129 | D31: EWY | E31: ETF | F31: Long | G31: 1 | H31: 1 | I31: 0 | J31: 0 | K31: 2 | L31: 153.72 | R31: 17.92 | S31: Broad risk-on — equity fresh highs, oil correction on Iran deal progress, vol compression deepening | T31: C | U31: Post-TSM-earnings; no fresh catalyst until Xi-Trump summit May-14/15. | V31: No | W31: OPEN | AE31: trade-rec-2026-04-17.md v1 | AF31: Prior EWY P001 executed 2026-04-15, HIT_STOP 2026-04-16 (+0.92% realized; stop-too-tight lesson in memory-lessons.md).
A32: N026 | B32: Near-Miss | C32: 46129 | D32: TSM | E32: Equity-single | F32: Long | G32: 1 | H32: 0 | I32: 0 | J32: 0 | K32: 1 | L32: 368.92 | R32: 17.92 | S32: Broad risk-on — equity fresh highs, oil correction on Iran deal progress, vol compression deepening | T32: T | U32: Residual momentum +1.00% → T=0 (near-zero; all raw TSMOM +78.52% factor-driven). Post-earnings sell-the-news damage -4.4% cumulative. | V32: No | W32: OPEN | AE32: trade-rec-2026-04-17.md v1 | AF32: Audit-addition (residual-mom) confirms flat idiosyncratic alpha.
A33: N027 | B33: Near-Miss | C33: 46129 | D33: NVDA | E33: Equity-single | F33: Long | G33: 1 | H33: 0 | I33: 0 | J33: 0 | K33: 1 | L33: 200.83 | R33: 17.92 | S33: Broad risk-on — equity fresh highs, oil correction on Iran deal progress, vol compression deepening | T33: T | U33: Residual -1.00% → T=0 (was +2 C-block Apr-16 N022; now downgraded by residual). | V33: No | W33: OPEN | AE33: trade-rec-2026-04-17.md v1 | AF33: Audit-addition (residual-mom) decision-moving downgrade.
A34: N028 | B34: Near-Miss | C34: 46129 | D34: AAPL | E34: Equity-single | F34: Long | G34: 0 | H34: 1 | I34: 0 | J34: 0 | K34: 1 | L34: 271.52 | R34: 17.92 | S34: Broad risk-on — equity fresh highs, oil correction on Iran deal progress, vol compression deepening | T34: S_and_C | U34: Residual +4.68% → T=+1 (strong today +3.08%). No S+1 quality case; no near-term catalyst. | V34: No | W34: OPEN | AE34: trade-rec-2026-04-17.md v1
A35: N029 | B35: Near-Miss | C35: 46129 | D35: AMZN | E35: Equity-single | F35: Long | G35: 1 | H35: 0 | I35: 1 | J35: 0 | K35: 2 | L35: 254.41 | R35: 17.92 | S35: Broad risk-on — equity fresh highs, oil correction on Iran deal progress, vol compression deepening | T35: T | U35: Residual +1.39% → T=0 (near-zero). Earnings Apr-23 critical binary (same day INTC). | V35: No | W35: OPEN | AE35: trade-rec-2026-04-17.md v1 | AF35: Audit-addition (residual-mom) blocks promotion; residual flat despite earnings cluster C+1.
A36: N030 | B36: Near-Miss | C36: 46129 | D36: META | E36: Equity-single | F36: Long | G36: 1 | H36: 0 | I36: 1 | J36: 0 | K36: 2 | L36: 685.17 | R36: 17.92 | S36: Broad risk-on — equity fresh highs, oil correction on Iran deal progress, vol compression deepening | T36: T | U36: Residual +0.75% → T=0. Earnings Apr-29 same-day FOMC critical binary. | V36: No | W36: OPEN | AE36: trade-rec-2026-04-17.md v1 | AF36: Audit-addition (residual-mom) blocks promotion.
A37: N031 | B37: Near-Miss | C37: 46129 | D37: WTI | E37: Commodity | F37: Long | G37: 1 | H37: 0 | I37: -1 | J37: 1 | K37: 1 | L37: 79.46 | R37: 17.92 | S37: Broad risk-on — equity fresh highs, oil correction on Iran deal progress, vol compression deepening | T37: T_and_C | U37: T=0 (trend weaker than Brent; 1m flattening). C=-1 (Iran Apr-21 binary bearish for oil). S+1 clean (basis-mom aligned-steepening, no divergence cap). | V37: No | W37: OPEN | AE37: trade-rec-2026-04-17.md v1 | AF37: Oil crash -9.27% intraday; partial contract-roll artifact possible.
A38: N032 | B38: Near-Miss | C38: 46129 | D38: BTC | E38: Crypto | F38: Long | G38: 0 | H38: 1 | I38: 1 | J38: 0 | K38: 2 | L38: 77775 | R38: 17.92 | S38: Broad risk-on — equity fresh highs, oil correction on Iran deal progress, vol compression deepening | T38: S | U38: Active-addresses STALE-WARN at 470k (3d stale); S upgraded 0 from -1 on price >$75k + ETF 3-day positive run through Apr-15. | V38: No | W38: OPEN | AE38: trade-rec-2026-04-17.md v1 | AF38: Funding negative 46+d = crowded-short squeeze setup (crowding filter, not trigger). FOMC Apr-28 = C+1.
A39: N033 | B39: Near-Miss | C39: 46129 | D39: PYPL | E39: Equity-single | F39: Short | G39: -1 | H39: -1 | I39: 0 | J39: 0 | K39: -2 | L39: 50.96 | R39: 17.92 | S39: Broad risk-on — equity fresh highs, oil correction on Iran deal progress, vol compression deepening | T39: R_and_C | U39: Residual -5.25% (aligns with raw -34.40%). Weakest single-stock. Short direction consistent. R=0 (intermediary z+0.18, no stress). | V39: No | W39: OPEN | AE39: trade-rec-2026-04-17.md v1 | AF39: Short-side near-miss logged for evidence trail. Promotion would need C=-1 catalyst or R=-1.

Sheet RegimeHistory
A1: Date | B1: Regime_Label | C1: Growth | D1: Inflation | E1: Policy | F1: FinConditions | G1: RiskOnOff | H1: BTC_VolRegime | I1: BTC_FundingBasis | J1: BTC_Structural | K1: Watch_Var_1 | L1: Watch_Var_2 | M1: Watch_Var_3 | N1: Promoted_Signals | O1: NearMiss_Count | P1: Source_Brief
A2: 46126 | B2: Energy-led reflation shock + hawkish repricing, softening at margin | C2: ambiguous | D2: reflationary | E2: on hold 3.50-3.75% | F2: easing (NFCI -0.43) | G2: cautious risk-on | H2: elevated spot volatility | I2: funding negative Binance | J2: active addr collapse 364k S=-1 | K2: Brent M1-M3 curve | L2: DXY breakdown sub-98 | M2: TSM earnings Apr-16 | N2: N001 (EWY) | O2: 8 | P2: market-brief-2026-04-14.md
A3: 46127 | B3: Post-shock reflation unwind → cautious risk-on | C3: ambiguous, deteriorating at margin | D3: reflationary (CPI +3.3%) | E3: on hold 3.50-3.75%; FOMC Apr 28-29 | F3: easing (NFCI -0.43; VIX 18.36) | G3: cautious risk-on | H3: spot pullback $74.3k | I3: ETF flows FLIPPED +$411.5M | J3: active addr 364k (stale) S=-1 | K3: Brent M1-M3 curve (EIA) | L3: DXY breakdown (sub-98) | M3: TSM earnings Apr-16 | N3: P001 (EWY), P003 (INTC) | O3: 5 | P3: market-brief-2026-04-15.md v1 + trade-rec v3
A4: 46128 | B4: Broad risk-on — equity records, vol compression, DXY sub-99. Iran binary Apr-21. | C4: ambiguous, improving at margin (TSM beat, SPX record) | D4: reflationary (CPI +3.3%, breakevens 2.36%) | E4: on hold 3.50-3.75%; FOMC Apr 28-29 | F4: easing (NFCI -0.47; VIX 18.19; MOVE 67.94) | G4: risk-on strengthening — equity records, vol compressing | H4: spot $74.9k, moderate vol | I4: negative funding 46d (crowded shorts); ETF +$411.5M | J4: active addr 470k recovered (+29% from 364k); hash rate 863 EH/s (-16.4%); S improved -1 to 0 | K4: Iran ceasefire expiry Apr-21 (binary) | L4: BTC active address recovery sustainability (470k) | M4: Big tech earnings week (TSLA/GOOGL Apr-22, INTC/AMZN Apr-23) | N4: SPY(+3), QQQ(+4), Gold(+3), EWY(+3 open) | O4: 4 | P4: market-brief-2026-04-16.md v1
A5: 46129 | B5: Broad risk-on — equity fresh highs, oil correction on Iran deal progress, vol compression deepening | C5: Ambiguous, improving at margin | D5: Reflationary (oil crash is disinflationary impulse) | E5: On hold 3.50-3.75% | F5: Easing further | G5: Risk-on strengthening | H5: Moderate vol | I5: Negative funding 46+ days | J5: Active addr 470k STALE-WARN; hash rate 1050 EH/s | K5: Oil crash (Brent -9.7% intraday, Iran deal progress) | L5: Big tech earnings cluster Apr-22/23/29 | M5: VIX/VIX3M 0.870 contango deepening | N5: SPY(+3), QQQ(+4,open), Gold(+3,open), INTC(+3,open,confirmed) | O5: 10 | P5: market-brief-2026-04-17 v3

Sheet VariableRegistry
A1: Var_ID | B1: Name | C1: Definition | D1: Asset_Class | E1: Category | F1: Horizon | G1: Use_Type | H1: Score_Component | I1: Evidence_Strength | J1: Status | K1: Discovery_Date | L1: Discovery_Source | M1: Source_Paper | N1: Intuition | O1: Peer_Reviewed | P1: Replicated | Q1: Mechanism_Grounded | R1: Independent_Info | S1: Realtime_Implementable | T1: Published_Sharpe | U1: Decay_Haircut_Pct | V1: Proj_Op_Sharpe | W1: Correlation_w_Existing | X1: Redundancy_Notes | Y1: Data_Source | Z1: Pull_Frequency | AA1: Lag | AB1: Double_Count_Gate | AC1: Last_Review_Date | AD1: Next_Review_Date | AE1: Review_History | AF1: Promotion_Date | AG1: Demotion_Date | AH1: Decision_Moving_Count | AI1: OOS_Contribution | AJ1: Notes
A2: V001 | B2: VIX | C2: CBOE Volatility Index; implied vol on SPX options | D2: Cross-Asset | E2: Volatility | F2: 1-4 weeks | G2: Risk Management | H2: R | I2: Grade A | J2: Grade A | L2: Foundational | M2: Whaley (2000) JD; extensive literature | N2: Fear gauge; high VIX = elevated risk premia, mean-reversion tendency | O2: PASS | P2: PASS | Q2: PASS | R2: PASS | S2: PASS | W2: Low (<0.3) with HY OAS in normal regimes; high (>0.7) in stress | Y2: CBOE / Yahoo ^VIX | Z2: Daily | AA2: 0d | AC2: 46127 | AD2: 46204 | AE2: Inaugural quarterly review 2026-04-15: RETAIN | AI2: Not yet assessed (0 closed signals) | AJ2: Core R-overlay input. VIX-at-entry conditioning added 2026-04-15.
A3: V002 | B3: MOVE Index | C3: Merrill Lynch Option Volatility Estimate; Treasury implied vol | D3: Cross-Asset | E3: Volatility | F3: 1-4 weeks | G3: Risk Management | H3: R | I3: Grade A | J3: Grade A | L3: Foundational | M3: Siriwardane (2019) JF | N3: Bond market stress indicator; leads equity vol by 1-2 weeks in crises | O3: PASS | P3: PASS | Q3: PASS | R3: PASS | S3: PASS | W3: Moderate with VIX (~0.5 normally, >0.8 in crises) | Y3: Refinitiv / Yahoo ^MOVE | Z3: Daily | AA3: 0d | AB3: Correlated with VIX in stress; take more negative signal | AC3: 46127 | AD3: 46204 | AE3: Quarterly 2026-04-15: RETAIN
A4: V003 | B4: DXY (Dollar Index) | C4: ICE US Dollar Index; weighted basket | D4: Cross-Asset | E4: Currency | F4: 1-3 months | G4: Directional | H4: S | I4: Grade A | J4: Grade A | L4: Foundational | M4: Verdelhan (2018) JF | N4: Strong dollar = headwind for commodities, EM, risk assets | O4: PASS | P4: PASS | Q4: PASS | R4: PASS | S4: PASS | W4: Moderate inverse with Gold (~-0.6), Brent (~-0.4) | Y4: ICE / Yahoo DX-Y.NYB | Z4: Daily | AA4: 0d | AC4: 46127 | AD4: 46204 | AE4: Quarterly 2026-04-15: RETAIN
A5: V004 | B5: HY OAS | C5: High Yield Option-Adjusted Spread; BAMLH0A0HYM2 | D5: Cross-Asset | E5: Credit | F5: 1-3 months | G5: Risk Management | H5: R | I5: Grade A | J5: Grade A | L5: Foundational | M5: Gilchrist-Zakrajsek (2012) AER | N5: Credit stress gauge; widening = risk-off, financial conditions tightening | O5: PASS | P5: PASS | Q5: PASS | R5: PASS | S5: PASS | W5: 0.65-0.75 with intermediary capital post-2008 | X5: Double-count gate with intermediary capital | Y5: FRED BAMLH0A0HYM2 | Z5: Daily | AA5: 1d | AB5: If both HY OAS and intermediary cap flag stress, take more negative — do not sum | AC5: 46127 | AD5: 46204 | AE5: Quarterly 2026-04-15: RETAIN
A6: V005 | B6: NFCI | C6: Chicago Fed National Financial Conditions Index | D6: Cross-Asset | E6: Financial conditions | F6: 1-3 months | G6: Risk Management | H6: R | I6: Grade A | J6: Grade A | L6: Foundational | M6: Brave-Butters (2012) | N6: Composite financial conditions; negative = easy, positive = tight | O6: PASS | P6: PASS | Q6: PASS | R6: PASS | S6: PASS | Y6: Chicago Fed weekly CSV | Z6: Weekly | AA6: 3-5d | AC6: 46127 | AD6: 46204 | AE6: Quarterly 2026-04-15: RETAIN
A7: V006 | B7: UST 2Y/10Y yields | C7: US Treasury yields DGS2/DGS10 | D7: Rates | E7: Yield curve | F7: 1-3 months | G7: Structural | H7: S | I7: Grade A | J7: Grade A | L7: Foundational | M7: Campbell-Shiller (1991); Adrian-Crump-Moench (2013) | N7: Term structure slope signals recession/expansion expectations | O7: PASS | P7: PASS | Q7: PASS | R7: PASS | S7: PASS | Y7: FRED DGS2/DGS10 | Z7: Daily | AA7: 1d | AC7: 46127 | AD7: 46204 | AE7: Quarterly 2026-04-15: RETAIN
A8: V007 | B8: Real yield / Breakevens | C8: 10Y TIPS real yield (DFII10) and breakeven (T10YIE) | D8: Rates | E8: Inflation expectations | F8: 1-3 months | G8: Structural | H8: S | I8: Grade A | J8: Grade A | L8: Foundational | M8: D'Amico et al. (2018) | N8: Real yields drive gold/commodity valuation; breakevens signal inflation expectations | O8: PASS | P8: PASS | Q8: PASS | R8: PASS | S8: PASS | W8: High with Gold (~-0.84 historically, broken post-2022) | X8: R² with Gold collapsed from 84% to 3-7% due to central bank buying | Y8: FRED DFII10/T10YIE | Z8: Daily | AA8: 1d | AC8: 46127 | AD8: 46204 | AE8: Quarterly 2026-04-15: RETAIN. Note: Gold R² regime break flagged in Trad core
A9: V008 | B9: ACM Term Premium 10Y | C9: Adrian-Crump-Moench term premium estimate | D9: Rates | E9: Term premium | F9: 3-12 months | G9: Structural | H9: S | I9: Grade A | J9: Grade A | L9: Foundational | M9: Adrian-Crump-Moench (2013) JFE | N9: Duration risk compensation; rising TP = tightening, falling = easing | O9: PASS | P9: PASS | Q9: PASS | R9: PASS | S9: PASS | Y9: NY Fed ACM CSV monthly | Z9: Monthly | AA9: 2-4w | AC9: 46127 | AD9: 46204 | AE9: Quarterly 2026-04-15: DATA GAP — frequently MISSING (monthly lag) | AJ9: Persistent MISSING issue due to monthly publication lag
A10: V009 | B10: Time-series momentum (TSMOM) | C10: 1m/3m/12m price momentum for indices/ETFs/commodities/FX/crypto | D10: All | E10: Momentum | F10: 1-4 weeks | G10: Timing | H10: T | I10: Grade A | J10: Grade A | L10: Foundational | M10: Moskowitz-Ooi-Pedersen (2012) JFE | N10: Trend-following across asset classes; positive autocorrelation at 1-12m horizons | O10: PASS | P10: PASS | Q10: PASS | R10: PASS | S10: PASS | T10: 0.9 | U10: 40 | V10: 0.54 | Y10: Derived from price series | Z10: Daily | AA10: 0d | AB10: For single stocks: prefer residual momentum (V026) over raw TSMOM | AC10: 46127 | AD10: 46204 | AE10: Quarterly 2026-04-15: RETAIN
A11: V010 | B11: Revision breadth | C11: Net earnings revision breadth across analyst estimates | D11: Equities | E11: Earnings | F11: 1-4 weeks | G11: Timing | H11: T | I11: Grade A | J11: Grade A | L11: Foundational | M11: Gleason-Lee (2003); multiple replication studies | N11: Analyst revisions contain information; breadth captures consensus shift direction | O11: PASS | P11: PASS | Q11: PASS | R11: PASS | S11: PASS | Y11: Zacks / I/B/E/S via SimplyWallSt | Z11: Weekly | AA11: 1-3d | AC11: 46127 | AD11: 46204 | AE11: Quarterly 2026-04-15: RETAIN
A12: V011 | B12: Brent M1-M3 curve slope | C12: Front-month to third-month futures curve shape | D12: Commodities | E12: Term structure | F12: 1-4 weeks | G12: Structural | H12: S | I12: Grade A | J12: Grade A | L12: Foundational | M12: Gorton-Hayashi-Rouwenhorst (2013) JF | N12: Backwardation = supply tightness, contango = oversupply; core commodity structural signal | O12: PASS | P12: PASS | Q12: PASS | R12: PASS | S12: PASS | W12: Supplemented by basis-momentum (V028) | X12: Static slope + basis-momentum = full curve picture | Y12: CME/ICE settlements, Barchart | Z12: Daily | AA12: 0d | AB12: Divergence cap with basis-momentum: if static slope=+1 but basis-mom flattening, cap S at 0 | AC12: 46127 | AD12: 46204 | AE12: Quarterly 2026-04-15: RETAIN
A13: V012 | B13: BTC active addresses | C13: Daily unique Bitcoin addresses transacting on-chain | D13: Crypto | E13: Network activity | F13: 1-3 months | G13: Structural | H13: S | I13: Grade A | J13: Grade A | L13: Foundational | M13: Liu-Tsyvinski (2021) JF; Cong-He-Li (2021) | N13: Network usage proxy; declining addresses = declining utility, bearish structural | O13: PASS | P13: PASS | Q13: PASS | R13: PASS | S13: PASS | Y13: blockchain.com / Glassnode free | Z13: Daily | AA13: 0-1d | AC13: 46127 | AD13: 46204 | AE13: Quarterly 2026-04-15: RETAIN. Currently STALE (Apr-12, 364k) | AJ13: Blocks BTC long: S=-1 when addresses collapse
A14: V013 | B14: BTC hash rate | C14: Total network hash rate (EH/s) | D14: Crypto | E14: Mining/Security | F14: Structural | G14: Structural | H14: S | I14: Grade A | J14: Grade A | L14: Foundational | M14: Cong-He-Li (2021) | N14: Security proxy; ATH hash rate = strong miner commitment | O14: PASS | P14: PASS | Q14: PASS | R14: PASS | S14: PASS | Y14: blockchain.com | Z14: Daily | AA14: 0-1d | AC14: 46127 | AD14: 46204 | AE14: Quarterly 2026-04-15: RETAIN
A15: V014 | B15: BTC exchange netflows | C15: Net BTC flow into/out of exchanges (CryptoQuant) | D15: Crypto | E15: Flow | F15: 1-5 days | G15: Timing | H15: T | I15: Grade A | J15: Grade A | L15: Foundational | M15: Aloosh-Ouzan-Shahzad (2023) | N15: Net outflow = accumulation (bullish); net inflow = distribution (bearish) | O15: PASS | P15: PASS | Q15: PASS | R15: PASS | S15: PASS | Y15: CryptoQuant free tier | Z15: Daily | AA15: 0-1d | AC15: 46127 | AD15: 46204 | AE15: Quarterly 2026-04-15: RETAIN
A16: V015 | B16: BTC realized vol | C16: Rolling 30d realized volatility from OHLC | D16: Crypto | E16: Volatility | F16: 1-4 weeks | G16: Risk Management | H16: R | I16: Grade A | J16: Grade A | L16: Foundational | M16: Liu-Tsyvinski (2021) JF | N16: Vol regime identification; high realized vol = crash-prone, apply larger stops | O16: PASS | P16: PASS | Q16: PASS | R16: PASS | S16: PASS | Y16: Derived from BTC OHLC (30d) | Z16: Daily | AA16: 0d | AC16: 46127 | AD16: 46204 | AE16: Quarterly 2026-04-15: RETAIN
A17: V026 | B17: Residual momentum (FF5) | C17: 12m return residualized against Fama-French 5-factor model for single stocks | D17: Equities | E17: Factor-adjusted momentum | F17: 1-3 months | G17: Timing | H17: T | I17: Grade A | J17: Approved | K17: 46126 | L17: Methodology audit | M17: Blitz-Huij-Martens (2011) JEF; Asness-Moskowitz-Pedersen (2013) JF | N17: Strips out beta/value/size/profitability/investment exposures; residual captures alpha momentum vs factor-driven momentum | O17: PASS | P17: PASS | Q17: PASS | R17: PASS | S17: PASS | T17: 0.7 | U17: 40 | V17: 0.42 | W17: Moderate with raw TSMOM; designed to be orthogonal | X17: Replaces raw TSMOM for single stocks when they disagree | Y17: Kenneth French library + derived OLS | Z17: Monthly | AA17: 1-2w | AB17: When raw TSMOM and residual conflict, trust residual (per Daniel-Moskowitz 2016) | AC17: 46127 | AD17: 46309 | AE17: Added 2026-04-14 audit. Quarterly 2026-04-15: early-CONFIRMED (decision-moving). Pipeline instability flagged. | AF17: 46126 | AH17: 8 | AI17: Decision-moving: promoted TSM, demoted AMZN/META, de-promoted TSM v3 | AJ17: 6-month review gate 2026-10-14. Pipeline produced different results in two same-day computes — stability issue to investigate.
A18: V027 | B18: Intermediary capital ratio | C18: NY Fed primary-dealer equity/total-capital ratio, z-score vs 3y rolling mean | D18: Cross-Asset | E18: Dealer constraints | F18: 1-3 months | G18: Risk Management | H18: R | I18: Grade A | J18: Approved | K18: 46126 | L18: Methodology audit | M18: He-Kelly-Manela (2017) JFE | N18: Dealer balance-sheet constraint leading indicator; z<-1σ = tightening before HY OAS widens | O18: PASS | P18: PASS | Q18: PASS | R18: PASS | S18: PASS | T18: 0.6 | U18: 40 | V18: 0.36 | W18: 0.65-0.75 with HY OAS post-2008 | X18: Double-count gate: if both flag stress, take more negative, not sum | Y18: NY Fed PD statistics weekly CSV | Z18: Weekly | AA18: ~1w | AB18: If z<-1σ: downgrade R by one notch on equities, commodities, FX longs. Do not double-count with HY OAS. | AC18: 46127 | AD18: 46309 | AE18: Added 2026-04-14 audit. Quarterly 2026-04-15: DATA GAP (z=+1.86, no downgrade triggered yet) | AF18: 46126 | AH18: 1 | AI18: Resolved EWY fail-loud caveat; no downgrade triggered (z positive) | AJ18: 6-month review gate 2026-10-14. Currently ample capacity (z=+1.86). Will only prove value if dealers tighten.
A19: V028 | B19: Basis-momentum | C19: 4w and 12w change in front-curve F1-F2 slope for commodities | D19: Commodities | E19: Curve dynamics | F19: 1-4 weeks | G19: Structural | H19: S | I19: Grade A | J19: Approved | K19: 46126 | L19: Methodology audit | M19: Boons-Prado (2019) JF | N19: Dynamic complement to static curve slope; catches curve-shape exhaustion that static slope misses | O19: PASS | P19: PASS | Q19: PASS | R19: PASS | S19: PASS | T19: 0.8 | U19: 40 | V19: 0.48 | W19: Supplements V011 (static curve slope); designed to be complementary | X19: Always used WITH static slope, never alone | Y19: Derived from front-curve daily settlements | Z19: Daily | AA19: 0d | AB19: Divergence cap: if static slope=+1 but basis-mom flattening, cap S at 0 | AC19: 46127 | AD19: 46309 | AE19: Added 2026-04-14 audit. Quarterly 2026-04-15: early-CONFIRMED (decision-moving). Divergence cap fired on WTI/Gold. | AF19: 46126 | AH19: 4 | AI19: Decision-moving: capped S at 0 for WTI and Gold (divergence); restored S to +1 when caps removed (v3) | AJ19: 6-month review gate 2026-10-14. Already the most active audit addition after 1 day.
A20: V016 | B20: BTC perp funding rate | C20: Perpetual swap funding rate (Binance, OKX) | D20: Crypto | E20: Crowding | F20: 1-5 days | G20: Risk Management | H20: R | I20: Grade B | J20: Grade A | L20: Foundational | M20: Practitioner; limited academic (Aloosh et al. 2023 partial) | N20: Negative funding = shorts paying longs (contrarian bullish); extreme positive = crowded longs | O20: PARTIAL | P20: PARTIAL | Q20: PASS | R20: PASS | S20: PASS | Y20: CoinGlass / Binance API | Z20: Daily | AA20: 0-1d | AC20: 46127 | AD20: 46204 | AE20: Grade B — thin academic coverage. Used as crowding filter, not return predictor.
A21: V017 | B21: BTC ETF net flows | C21: Daily net flows into/out of US spot Bitcoin ETFs | D21: Crypto | E21: Institutional flow | F21: 1-5 days | G21: Timing | H21: T | I21: Grade B | J21: Grade A | L21: Post-ETF era (2024+) | M21: No direct academic paper; institutional flow literature | N21: Institutional demand proxy; streak of outflows = de-risking, inflows = accumulation | O21: FAIL | P21: FAIL | Q21: PASS | R21: PASS | S21: PASS | Y21: Farside Investors / CoinDesk | Z21: Daily | AA21: 0-1d | AC21: 46127 | AD21: 46204 | AE21: Grade B — too new for replication. Post-ETF factor stability unknown. | AJ21: Open research question: does this decay as BTC ETF market matures?
A22: V018 | B22: BTC 3m basis | C22: Annualized 3-month futures basis (Deribit/CME) | D22: Crypto | E22: Carry/Crowding | F22: 1-4 weeks | G22: Risk Management | H22: R | I22: Grade B | J22: Grade A | L22: Foundational | M22: Practitioner; carry trade literature | N22: High basis = crowded long (bearish lean); negative basis = bearish positioning | O22: PARTIAL | P22: PARTIAL | Q22: PASS | R22: PASS | S22: PASS | Y22: Deribit / CME basis | Z22: Daily | AA22: 0-1d | AC22: 46127 | AD22: 46204 | AE22: Grade B. Persistently MISSING in pipeline (Deribit data unreliable).
A23: V019 | B23: MVRV / SOPR | C23: Market Value to Realized Value ratio; Spent Output Profit Ratio | D23: Crypto | E23: On-chain valuation | F23: 1-3 months | G23: Structural | H23: S | I23: Grade B | J23: Grade A | L23: On-chain analytics | M23: Limited academic (practitioner-dominant) | N23: MVRV>3 historically preceded corrections; SOPR<1 = holders selling at loss (capitulation) | O23: FAIL | P23: PARTIAL | Q23: PASS | R23: PASS | S23: PASS | Y23: Glassnode free | Z23: Daily | AA23: 0-1d | AC23: 46127 | AD23: 46204 | AE23: Grade B — regime context only. No return-timing evidence for Grade A.
A24: V020 | B24: News sentiment | C24: Aggregated news sentiment scores for universe assets | D24: All | E24: Sentiment | F24: 1-5 days | G24: Timing | H24: C | I24: Grade B | J24: Grade A | L24: Foundational | M24: Tetlock (2007) JF; Garcia (2013) | N24: Negative sentiment predicts short-term reversals; positive sentiment has weaker signal | O24: PASS | P24: PASS | Q24: PASS | R24: PASS | S24: PARTIAL | T24: 0.4 | U24: 40 | V24: 0.24 | Y24: News-events skill captures qualitative | Z24: Daily | AA24: 0d | AC24: 46127 | AD24: 46204 | AE24: Grade B — regime-dependent; quantitative scoring not implemented
A25: V029 | B25: GEX (Gamma Exposure) | C25: Net gamma exposure of options market makers on SPX/QQQ | D25: Equities | E25: Market microstructure | F25: 1-5 days | G25: Regime Filter | H25: Overlay | I25: Provisional | J25: Candidate | K25: 46127 | L25: Quarterly review pipeline | M25: Barbon-Buraschi (2021); practitioner research | N25: Positive GEX = dealers hedge by selling rallies/buying dips (mean-reverting); negative GEX = pro-cyclical hedging (trending) | O25: PASS | P25: PARTIAL | Q25: PASS | R25: PASS | S25: PARTIAL | Y25: SpotGamma / SqueezeMetrics (paid); proxies possible | Z25: Daily | AA25: 0d | AC25: 46127 | AD25: 46204 | AE25: Tier 2 candidate. Needs data collection infrastructure. | AH25: 0 | AJ25: Quarterly review 2026-04-15: DEFER (need signal count). Real-time implementability depends on free proxy.
A26: V030 | B26: Cross-asset lead-lag | C26: Systematic lead-lag relationships: BTC→ETH, NVDA→semis, Copper→ISM, MOVE→VIX | D26: Cross-Asset | E26: Lead-lag | F26: 1-5 days | G26: Timing | H26: T | I26: Provisional | J26: Candidate | K26: 46127 | L26: Quarterly review pipeline | M26: Lo-MacKinlay (1990) RFS; Asness-Moskowitz-Pedersen (2013) | N26: Some assets systematically lead others due to information diffusion or liquidity differences | O26: PASS | P26: PASS | Q26: PASS | R26: PARTIAL | S26: PASS | W26: May overlap with TSMOM for the led asset | Y26: Derived from existing price series | Z26: Daily | AA26: 0d | AC26: 46127 | AD26: 46204 | AE26: Tier 2 candidate. Can retroactively tag with existing data. | AH26: 0 | AJ26: Quarterly review 2026-04-15: DEFER.
A27: V031 | B27: Correlation-regime signal quality | C27: Trailing 20d cross-asset correlation as quality filter | D27: Cross-Asset | E27: Regime | F27: 1-4 weeks | G27: Regime Filter | H27: Overlay | I27: Provisional | J27: Candidate | K27: 46127 | L27: Quarterly review pipeline | M27: Kritzman et al. (2011) FAJ (absorption ratio) | N27: High cross-asset correlation = correlation-1 crisis regime; signals less reliable due to factor dominance | O27: PASS | P27: PASS | Q27: PASS | R27: PASS | S27: PASS | Y27: Derived from existing price series | Z27: Daily | AA27: 0d | AC27: 46127 | AD27: 46204 | AE27: Tier 2 candidate. Needs 30+ closed signals. | AH27: 0 | AJ27: Quarterly review 2026-04-15: DEFER.
A28: V032 | B28: Decision tree feature importance | C28: Shallow decision tree to surface non-obvious interaction effects in scoring | D28: All | E28: Machine learning | F28: N/A | G28: Regime Filter | H28: Overlay | I28: Ungraded | J28: Candidate | K28: 46127 | L28: Quarterly review pipeline | M28: Gu-Kelly-Xiu (2020) RFS | N28: Data-driven feature importance; may reveal interactions the hand-coded interaction matrix misses | O28: PASS | P28: PASS | Q28: PASS | R28: N/A | S28: PASS | W28: Meta-variable, not standalone | Y28: Derived from ledger data | Z28: Quarterly | AA28: 0d | AC28: 46127 | AD28: 46204 | AE28: Tier 3 candidate. Needs 50+ closed signals. | AH28: 0 | AJ28: Quarterly review 2026-04-15: DEFER.
A29: V033 | B29: Calendar/seasonal effects | C29: Day-of-week, OpEx proximity, FOMC week patterns | D29: All | E29: Calendar | F29: 1-5 days | G29: Timing | H29: C | I29: Ungraded | J29: Candidate | K29: 46127 | L29: Quarterly review pipeline | M29: Lucca-Moench (2015) JF (pre-FOMC drift) | N29: Well-documented calendar anomalies; FOMC week drift is strongest | O29: PASS | P29: PASS | Q29: PARTIAL | R29: PASS | S29: PASS | T29: 0.3 | U29: 50 | V29: 0.15 | Y29: Derived from calendar | Z29: Daily | AA29: 0d | AC29: 46127 | AD29: 46204 | AE29: Tier 3 candidate. Needs 60+ closed signals. Low projected Sharpe. | AH29: 0 | AJ29: Quarterly review 2026-04-15: DEFER. Projected operational Sharpe below 0.3 — may not be worth complexity.

Sheet CatalystLog
A1: Date_Added | B1: Catalyst_Date | C1: Event | D1: Assets_Affected | E1: Impact_Level | F1: Expectation | G1: Outcome | H1: Outcome_Date | I1: Actual_vs_Expected | J1: Market_Reaction | K1: Signals_Dependent | L1: Source_File
A2: 46126 | B2: 46127 | C2: Goldman Sachs BTC ETF filing | D2: BTC | E2: High | F2: Institutional entry signal | G2: SURPRISE | H2: 46127 | I2: +$411.5M ETF inflows | J2: BTC spot $75.9k high then pullback to $74.3k | K2: N/A | L2: news-2026-04-15.md
A3: 46126 | B3: 46127 | C3: EIA weekly crude inventories | D3: Brent, WTI | E3: High | F3: Draw expected | G3: BULLISH SURPRISE: -0.9 Mb draw vs +2.1 Mb consensus. Gasoline -6.3 Mb, distillate -3.1 Mb. Oil FAILED to rally. | K3: Brent, WTI signals | L3: market-brief-2026-04-15.md
A4: 46126 | B4: 46128 | C4: TSM Q1 earnings (02:00 ET) | D4: TSM, NVDA, QQQ, EWY | E4: High | F4: Cons EPS $3.26, rev $35.4B (+38% y/y) | G4: BEAT: Rev $35.9B (+35% y/y), GM 66.2%, Q2 guide $39-40.2B | K4: P001, P003 | L4: trade-rec-2026-04-15.md
A5: 46127 | B5: 46129 | C5: Monthly options expiry; UMich prelim | D5: SPY, QQQ, DXY | E5: Medium | F5: Positioning flush | G5: PENDING | L5: news-2026-04-15.md
A6: 46127 | B6: 46133 | C6: Iran ceasefire expires | D6: Brent, WTI, Gold, VIX | E6: High | F6: Binary: talks resume vs escalation | G6: PENDING | K6: N012 (Brent) | L6: trade-rec-2026-04-15.md
A7: 46127 | B7: 46135 | C7: INTC Q1 earnings (after close) | D7: INTC, QQQ | E7: High | F7: Guided rev $11.7-$12.7B; Terafab validation | G7: PENDING | K7: P003 | L7: trade-rec-2026-04-15.md v3
A8: 46127 | B8: 46140 | C8: FOMC Apr 28-29 | D8: All | E8: High | F8: Statement + dots; path repricing | G8: PENDING | L8: market-brief-2026-04-15.md
A9: 46128 | B9: 46129 | C9: Monthly options expiry; UMich prelim sentiment | D9: SPY, QQQ, DXY | E9: Medium | F9: Positioning flush | G9: PENDING
A10: 46128 | B10: 46134 | C10: TSLA Q1 earnings (after close) | D10: TSLA, QQQ | E10: High | F10: Cons EPS $0.38, rev $22.6B | G10: PENDING
A11: 46128 | B11: 46134 | C11: GOOGL Q1 earnings | D11: GOOGL, QQQ | E11: High | F11: Ad revenue + cloud; could push Sum toward +3 | G11: PENDING
A12: 46129 | B12: 46129 | C12: France-UK Hormuz defensive multilateral mission online meeting | D12: BRENT, WTI, GOLD, VIX | E12: Med | F12: Escalation-management; not binary | G12: PENDING (meeting today; result awaited) | L12: catalysts-cache-2026-04-17.json
A13: 46129 | B13: 46133 | C13: Iran ceasefire expires (catalysts cache; Memory carries Apr-22) | D13: BRENT, WTI, GOLD, VIX, SPY, QQQ | E13: Critical | F13: Binary: deal = risk-on / oil down; collapse = Gold/VIX bid | G13: PENDING | L13: catalysts-cache-2026-04-17.json
A14: 46129 | B14: 46140 | C14: USTR Section 301 public hearing (China/Taiwan/others) | D14: EWY, TSM, INTC, SPY | E14: Med | F14: Alt tariff pathway post-SCOTUS Sec-122 ruling | G14: PENDING | L14: catalysts-cache-2026-04-17.json
A15: 46129 | B15: 46141 | C15: ECB rate decision | D15: EURUSD, DXY | E15: High | F15: Same day as FOMC | G15: PENDING | L15: catalysts-cache-2026-04-17.json
A16: 46129 | B16: 46142 | C16: BoE rate decision | D16: GBPUSD, DXY | E16: Med | F16: Neutral | G16: PENDING | L16: catalysts-cache-2026-04-17.json

Sheet DataQuality
A1: Date | B1: Total_GradeA_Vars | C1: Missing_Count | D1: Missing_Rate_Pct | E1: Missing_Variables | F1: Stale_Count | G1: Stale_Variables | H1: Audit_ResidMom_Status | I1: Audit_IntCap_Status | J1: Audit_BasisMom_Status | K1: Pipeline_Health | L1: Source_Brief | M1: Notes | N1: T1_Count | O1: T2_Count | P1: T3_Cache_Count | Q1: T4_Missing_Count | R1: Retrieval_Time_Sec | S1: Cache_Coverage_Pct
A2: 46126 | B2: 28 | C2: 4 | D2: 14.3 | E2: ACM TP 10Y, BTC active addr (stale), BTC 3m basis, BTC funding | F2: 2 | G2: VIX3M (3d stale), Palladium | H2: MISSING | I2: MISSING | J2: MISSING | K2: DEGRADED | L2: market-brief-2026-04-14.md | M2: First day; audit additions not yet computed
A3: 46127 | B3: 28 | C3: 4 | D3: 14.3 | E3: ACM TP 10Y, BTC active addr (stale Apr-12), BTC 3m basis, BTC funding | F3: 2 | G3: VIX3M (5d stale), Palladium | H3: LIVE | I3: LIVE | J3: LIVE | K3: OPERATIONAL | L3: market-brief-2026-04-15.md | M3: All 3 audit-addition pipelines now LIVE
A4: 46128 | B4: 3 | C4: 0 | D4: 0 | E4: none | F4: LIVE | G4: STALE-OK | H4: LIVE | I4: T1:2, T2:0, T3:1, T4:0 | J4: ALL_UP | K4: preflight-audit-data | L4: All sources reachable. ResidMom 12/12 via FF5 OLS. IntCap from cache (STALE-OK, 12d). BasisMom 5/5 F1-F2 via Yahoo. | M4: audit-data-staging-2026-04-16.md not produced. All 3 audit variables fail-loud. 12 single-stock T-legs blocked.
A5: 46129 | B5: 39 | C5: 0 | D5: 0 | E5: Residual momentum (staging compute error: SPY column not found in stock returns — FF5 input) | F5: 2 | G5: BTC_ActiveAddr (3d STALE-WARN), ACM_TP_10Y (Jan-2026 STALE) | H5: LIVE | I5: LIVE | J5: LIVE | K5: OPERATIONAL | L5: market-brief-2026-04-17 v3 | M5: First zero-MISSING Grade A session since audit-adds. All 3 audit-addition vars LIVE. Oil crash -9.7% Brent (possible contract-roll + Iran deal progress). | N5: 34 | O5: 3 | P5: 2 | Q5: 0

Sheet AuditAdditionLog
A1: Date | B1: Variable | C1: Asset | D1: Direction_of_Move | E1: Score_Leg_Before | F1: Score_Leg_After | G1: Impact_on_Sum | H1: Decision_Moving | I1: Source_File
A2: 46127 | B2: Intermediary capital ratio | C2: EWY | D2: z=+1.86, R stays 0 → resolved fail-loud caveat | E2: MISSING | F2: 0 | G2: EWY Sum=+3 now clean | H2: YES | I2: weekly-review-2026-04-15.md
A3: 46127 | B3: Residual momentum | C3: All 12 stocks | D3: T=0 for all → lifted T-block | E3: MISSING | F3: 0 | G3: No promotions | H3: NO | I3: audit-data-staging-2026-04-15.md
A4: 46127 | B4: Basis-momentum | C4: WTI | D4: Divergence cap fired → S capped at 0 | E4: +1 | F4: 0 | G4: Sum demoted | H4: YES | I4: audit-data-staging-2026-04-15.md
A5: 46127 | B5: Basis-momentum | C5: Gold | D5: Divergence cap fired → S capped at 0 | E5: +1 | F5: 0 | G5: Sum demoted | H5: YES | I5: audit-data-staging-2026-04-15.md
A6: 46127 | B6: Residual momentum | C6: TSM | D6: T: 0→+1 (residual +20.6%), promotes Sum +2→+3 | E6: 0 | F6: +1 | G6: Promoted to P002 | H6: YES | I6: trade-rec-2026-04-15.md v2
A7: 46127 | B7: Residual momentum | C7: AMZN | D7: T: 0→-1 (residual -9.3%), demotes Sum +2→+1 | E7: 0 | F7: -1 | G7: Dropped from near-miss | H7: YES | I7: trade-rec-2026-04-15.md v2
A8: 46127 | B8: Residual momentum | C8: META | D8: T: 0→-1 (residual -12.1%), demotes Sum +2→+1 | E8: 0 | F8: -1 | G8: Dropped from near-miss | H8: YES | I8: trade-rec-2026-04-15.md v2
A9: 46127 | B9: Residual momentum | C9: TSM | D9: T: +1→-1 (residual flipped +20.6%→-19.78%) | E9: +1 | F9: -1 | G9: DE-PROMOTED Sum +3→+1 | H9: YES | I9: trade-rec-2026-04-15.md v3
A10: 46127 | B10: Residual momentum | C10: GOOGL | D10: T: +1→0 (residual +29.9%→-0.20%) | E10: +1 | F10: 0 | G10: Demoted Sum +2→+1 | H10: YES | I10: trade-rec-2026-04-15.md v3
A11: 46127 | B11: Residual momentum | C11: MU | D11: T: +1→0 (residual +88.5%→+1.44%) | E11: +1 | F11: 0 | G11: Demoted Sum +2→+1 | H11: YES | I11: trade-rec-2026-04-15.md v3
A12: 46127 | B12: Basis-momentum | C12: WTI | D12: Divergence cap removed → S restored to +1 | E12: 0 | F12: +1 | G12: Sum restored +0→+2 | H12: YES | I12: trade-rec-2026-04-15.md v3
A13: 46127 | B13: Basis-momentum | C13: Gold | D13: Divergence cap removed → S restored to +1 | E13: 0 | F13: +1 | G13: Sum restored +1→+2 | H13: YES | I13: trade-rec-2026-04-15.md v3
... A24: 46129 | B24: Basis-momentum (4w/12w) | C24: ALL 5 commodities | D24: All 5 computed; Brent/WTI/Copper aligned-steepening (no cap); Gold/Silver static contango (cap N/A) | E24: variable | F24: variable | G24: No divergence cap fires today | H24: NO | I24: trade-rec-2026-04-17.md v1

Sheet PerformanceStats
A1: Performance Statistics
A3: Metric | B3: Value | C3: Formula
A4: Total Signals | B4: =COUNTA(SignalLedger!A2:A10000) | C4: Count all logged signals
A5: Promoted Signals | B5: =COUNTIF(SignalLedger!B2:B10000,"Promoted") | C5: Type = Promoted
A6: Near-Miss Signals | B6: =COUNTIF(SignalLedger!B2:B10000,"Near-Miss") | C6: Type = Near-Miss
A7: Open Signals | B7: =COUNTIF(SignalLedger!W2:W10000,"OPEN") | C7: Status = OPEN
A8: Hit Target | B8: =COUNTIF(SignalLedger!W2:W10000,"HIT_TARGET") | C8: Status = HIT_TARGET
A9: Hit Stop | B9: =COUNTIF(SignalLedger!W2:W10000,"HIT_STOP") | C9: Status = HIT_STOP
A10: Expired | B10: =COUNTIF(SignalLedger!W2:W10000,"EXPIRED") | C10: Status = EXPIRED
A11: Win Rate (closed only) | B11: =IFERROR(COUNTIF(SignalLedger!W2:W10000,"HIT_TARGET")/(COUNTIF(SignalLedger!W2:W10000,"HIT_TARGET")+COUNTIF(SignalLedger!W2:W10000,"HIT_STOP")+COUNTIF(SignalLedger!W2:W10000,"EXPIRED")),"-") | C11: Target/(Target+Stop+Expired)
A12: Avg Hypo P&L % | B12: =IFERROR(AVERAGEIF(SignalLedger!AD2:AD10000,"<>"&""),"-") | C12: Average non-blank P&L
A13: Days in Operation | B13: =IFERROR(MAX(SignalLedger!C2:C10000)-MIN(SignalLedger!C2:C10000),0) | C13: Max date - Min date
A16: By Asset Class
A17: Asset Class | B17: Signal Count | C17: Win Rate | D17: Avg Move %
A18: Crypto | B18: =COUNTIF(SignalLedger!E2:E10000,"Crypto") | C18: - | D18: -
A19: Equities | B19: =COUNTIF(SignalLedger!E2:E10000,"Equities") | C19: - | D19: -
A20: ETFs/Indices | B20: =COUNTIF(SignalLedger!E2:E10000,"ETFs/Indices") | C20: - | D20: -
A21: Commodities | B21: =COUNTIF(SignalLedger!E2:E10000,"Commodities") | C21: - | D21: -
A22: FX | B22: =COUNTIF(SignalLedger!E2:E10000,"FX") | C22: - | D22: -
A25: By Score Component (when = +1)
A26: Component | B26: +1 Count | C26: +1 Win Rate | D26: -1 Count | E26: -1 Win Rate
A27: S | B27: =COUNTIF(SignalLedger!G2:G10000,1) | C27: - | D27: =COUNTIF(SignalLedger!G2:G10000,-1) | E27: -
A28: T | B28: =COUNTIF(SignalLedger!H2:H10000,1) | C28: - | D28: =COUNTIF(SignalLedger!H2:H10000,-1) | E28: -
A29: C | B29: =COUNTIF(SignalLedger!I2:I10000,1) | C29: - | D29: =COUNTIF(SignalLedger!I2:I10000,-1) | E29: -
A30: R | B30: =COUNTIF(SignalLedger!J2:J10000,1) | C30: - | D30: =COUNTIF(SignalLedger!J2:J10000,-1) | E30: -
A33: Variable Registry Summary
A34: Status | B34: Count
A35: Candidate | B35: =COUNTIF(VariableRegistry!J2:J10000,"Candidate")
A36: Watchlist | B36: =COUNTIF(VariableRegistry!J2:J10000,"Watchlist")
A37: Under Review | B37: =COUNTIF(VariableRegistry!J2:J10000,"Under Review")
A38: Provisionally Useful | B38: =COUNTIF(VariableRegistry!J2:J10000,"Provisionally Useful")
A39: Approved | B39: =COUNTIF(VariableRegistry!J2:J10000,"Approved")
A40: Grade A | B40: =COUNTIF(VariableRegistry!J2:J10000,"Grade A")
A41: Rejected | B41: =COUNTIF(VariableRegistry!J2:J10000,"Rejected")
A42: Retired | B42: =COUNTIF(VariableRegistry!J2:J10000,"Retired")

Sheet README
A1: Master Data Log — Architecture Documentation
A3: Created: 2026-04-15
A4: Purpose: Structured analytical data store for Gerald's trading workspace
A6: SHEET DESCRIPTIONS:
A8: DailyVariables | B8: One row per trading day. All Grade A/B variable readings from the market brief.
B9: Producer: market-brief skill (appends row daily at 20:00 UTC+8)
B10: Consumer: signal-review, quarterly-methodology-review
A12: SignalLedger | B12: All promoted and near-miss signals. Mirrors hypo-ledger-2026.md in structured form.
B13: Producer: daily-trade-rec skill (appends rows at 20:25 UTC+8)
B14: Consumer: signal-review (marks-to-market weekly), quarterly-review
A16: RegimeHistory | B16: Daily regime label and state dimensions. One row per trading day.
B17: Producer: market-brief skill
B18: Consumer: signal-review (regime-conditional analysis)
A20: VariableRegistry | B20: The variable discovery and lifecycle system.
B21: Status ladder: Candidate → Watchlist → Under Review → Provisionally Useful → Approved → Grade A
B22: Producers: literature-review (semi-annual), market-brief (daily observations), quarterly-review (promotions)
B23: Review cadence: Daily add, Weekly clean, Monthly watchlist review, Quarterly promote/demote
A25: CatalystLog | B25: Named catalysts and their resolution outcomes.
B26: Producer: daily-trade-rec skill (from §4 catalyst map)
B27: Consumer: signal-review (catalyst resolution tracking)
A29: DataQuality | B29: Daily data completeness tracking. MISSING rates and pipeline health.
B30: Producer: market-brief and preflight-check skills
B31: Consumer: quarterly-review (data pipeline audit)
A33: AuditAdditionLog | B33: Contribution log for the three audit-addition variables.
B34: Replaces Memory.md §10. Evidence base for the 2026-10-14 review.
B35: Producer: daily-trade-rec skill
A37: PerformanceStats | B37: Summary formulas referencing SignalLedger. Auto-computed.
B38: Includes win rates, asset class breakdowns, score component analysis, variable registry summary.
A40: RULES:
A41: 1. SignalLedger is append-only. Never delete or retroactively edit rows.
A42: 2. DailyVariables: one row per trading day. Overwrite only if same-day correction (note in Source_Brief).
A43: 3. VariableRegistry: variables can change status but are never deleted. Rejected/Retired variables stay for audit trail.
A44: 4. Markdown files remain the human-readable presentation layer. This workbook is the analytical layer.
A45: 5. If markdown and Excel diverge, Excel is source of truth for quantitative data.
A47: VARIABLE DISCOVERY SYSTEM:
A48: Status Ladder:
A49: Candidate — plausible idea, not yet assessed
A50: Watchlist — weak or mixed evidence, worth tracking over time
A51: Under Review — being actively assessed with data
A52: Provisionally Useful — seems helpful but not fully trusted (pilot phase)
...
